Workbook

Sheet Prices
A1: Insurgency: Sandstorm | B1: 39.99
A2: Insurgency: Sandstorm - Gold Edition | B2: 69.99
A3: Insurgency: Sandstorm - Y1 and Y2 Passes | B3: -
A4: Insurgency: Sandstorm - Deluxe Edition | B4: 49.99
A5: Insurgency: Sandstorm - Ultimate Edition | B5: 79.99
A6: Insurgency: Sandstorm - Year Pass 1 + 2 | B6: 44.99
A7: Insurgency: Sandstorm - Year Pass 1 + 2 + 3 | B7: 59.99
A8: Insurgency: Sandstorm - Year Pass 3 | B8: 34.99
A9: SnowRunner - 1-Year Anniversary Edition | B9: 39.99
A10: SnowRunner - Year 1 Pass | B10: 24.99
A11: SnowRunner - 2-Year Anniversary Edition | B11: 69.99
A12: SnowRunner - 4-Year Anniversary Edition | B12: 109.99
A13: SnowRunner - 2-Year Anniversary Edition Upgrade | B13: 39.99
A14: SnowRunner - 3-Year Anniversary Edition Upgrade | B14: 59.99
A15: SnowRunner - 4-Year Anniversary Edition Upgrade | B15: 79.99
... A17: SnowRunner - 3-Year Anniversary Edition | B17: 79.99
A18: SnowRunner - DLCs | B18: -
A19: SnowRunner - Seasons 1 to 12 | B19: -
A20: SnowRunner - Season 13 | B20: 6.99
A21: SnowRunner - Seasons 14 | B21: 6.99
A22: SnowRunner - Year 2 Pass | B22: 24.99
A23: SnowRunner - Year 3 Pass | B23: 24.99
A24: Expeditions Base Game | B24: 49.99
A25: Expeditions Supreme Edition | B25: 79.99
A26: Expeditions Year 1 Edition | B26: 69.99
A27: Warhammer 40,000 : Space Marine 2 | B27: 69.99
A28: Warhammer 40,000: Space Marine 2 - Ultra Edition | B28: 109.99
A29: Warhammer 40,000 : Space Marine 2 - Gold Edition | B29: 99.99
A30: Warhammer 40,000: Space Marine 2 - Gold Edition | B30: 99.99
A31: Warhammer 40,000: Space Marine 2 - DLCs | B31: -
A32: Warhammer 40,000: Space Marine 2 - Season Pass | B32: 39.99
A33: Warhammer 40,000: Space Marine 2 | B33: 69.99

Sheet SM2 2026
A1: 2026
A2: Start Date | B2: End Date | C2: Program | D2: Content Name | E2: Current SRP ($USD) | F2: Promo SRP ($USD) | G2: Discount %
A3: STEAM
A4: 46030 | B4: 46044 | C4: Custom Sales | D4: Warhammer 40,000: Space Marine 2 | E4: 59.99 | F4: =E4*(1-G4) -> 23.996 | G4: 0.6
A5: 46030 | B5: 46044 | C5: Custom Sales | D5: Warhammer 40,000: Space Marine 2 1 Year Anniversary | E5: 89.99 | F5: =E5*(1-G5) -> 35.996 | G5: 0.6
A6: 46030 | B6: 46044 | C6: Custom Sales | D6: Warhammer 40,000: Space Marine 2 Ultra Edition | E6: 99.99 | F6: =E6*(1-G6) -> 49.995 | G6: 0.5
A7: 46030 | B7: 46044 | C7: Custom Sales | D7: Warhammer 40,000: Space Marine 2 2 Year Anniversary | E7: 119.99 | F7: =E7*(1-G7) -> 79.1934 | G7: 0.34
A8: 46030 | B8: 46044 | C8: Custom Sales | D8: Warhammer 40,000: Space Marine 2 - Season Pass | E8: 39.99 | F8: =E8*(1-G8) -> 29.9925 | G8: 0.25
A9: 46030 | B9: 46044 | C9: Custom Sales | D9: Warhammer 40,000: Space Marine 2 - DLC 1,3 | E9: 4.99 | F9: =E9*(1-G9) -> 3.992 | G9: 0.2
A10: 46030 | B10: 46044 | C10: Custom Sales | D10: Warhammer 40,000: Space Marine 2 - OST | E10: 6.99 | F10: =E10*(1-G10) -> 5.592 | G10: 0.2
A11: 46030 | B11: 46044 | C11: Custom Sales | D11: Warhammer 40,000: Space Marine 2 - Artbook | E11: 7.99 | F11: =E11*(1-G11) -> 6.392 | G11: 0.2
A12: 46030 | B12: 46044 | C12: Custom Sales | D12: Warhammer 40,000: Space Marine 2 - DLC 4 (Dark Angels) | E12: 9.99 | F12: =E12*(1-G12) -> 7.992 | G12: 0.2
A13: 46030 | B13: 46044 | C13: Custom Sales | D13: Warhammer 40,000: Space Marine 2 - DLC 8 (Salamanders) | E13: 7.99 | F13: =E13*(1-G13) -> 6.392 | G13: 0.2
A14: 46030 | B14: 46044 | C14: Custom Sales | D14: Warhammer 40,000: Space Marine 2 - DLC 7 (Raven Guard) | E14: 4.99 | F14: =E14*(1-G14) -> 3.992 | G14: 0.2
A15: 46030 | B15: 46044 | C15: Custom Sales | D15: Warhammer 40,000: Space Marine 2 - DLC 5 (Space Wolves) | E15: 9.99 | F15: =E15*(1-G15) -> 7.992 | G15: 0.2
... A143: 46219 | B143: 46233 | C143: Custom Sales | D143: Warhammer 40,000: Space Marine 2 - DLC 15 (Blood Angels champion) | E143: 7.99 | F143: =E143*(1-G143) -> 5.9925 | G143: 0.25
A144: 46219 | B144: 46233 | C144: Custom Sales | D144: Warhammer 40,000: Space Marine 2 - DLC 17 (Carcharodons cosmectic) | E144: 4.99 | F144: =E144*(1-G144) -> 3.7425 | G144: 0.25 | H144: Feb
A145: 46219 | B145: 46233 | C145: Custom Sales | D145: Warhammer 40,000: Space Marine 2 - DLC 16 (Raven guards) | E145: 7.99 | F145: =E145*(1-G145) -> 5.9925 | G145: 0.25 | H145: Feb
A146: 46219 | B146: 46233 | C146: Custom Sales | D146: Warhammer 40,000: Space Marine 2 - DLC 18 (Iron Hands) | E146: 9.99 | F146: =E146*(1-G146) -> 7.992 | G146: 0.2 | H146: May
A148: 46268 | B148: 46279 | C148: Publisher Sales | D148: Warhammer 40,000: Space Marine 2 | E148: 59.99 | F148: =E148*(1-G148) -> 17.997 | G148: 0.7
A149: 46268 | B149: 46279 | C149: Publisher Sales | D149: Warhammer 40,000: Space Marine 2 1 Year Anniversary | E149: 89.99 | F149: =E149*(1-G149) -> 26.997 | G149: 0.7
A150: 46268 | B150: 46279 | C150: Publisher Sales | D150: Warhammer 40,000: Space Marine 2 Ultra Edition | E150: 99.99 | F150: =E150*(1-G150) -> 49.995 | G150: 0.5
A151: 46268 | B151: 46279 | C151: Publisher Sales | D151: Warhammer 40,000: Space Marine 2 2 Year Anniversary | E151: 119.99 | F151: =E151*(1-G151) -> 53.9955 | G151: 0.55
A152: 46268 | B152: 46279 | C152: Publisher Sales | D152: Warhammer 40,000: Space Marine 2 - Season Pass | E152: 39.99 | F152: =E152*(1-G152) -> 27.993 | G152: 0.3
A153: 46268 | B153: 46279 | C153: Publisher Sales | D153: Warhammer 40,000: Space Marine 2 - Season Pass 2 | E153: 39.99 | F153: =E153*(1-G153) -> 29.9925 | G153: 0.25
A154: 46268 | B154: 46279 | C154: Publisher Sales | D154: Warhammer 40,000: Space Marine 2 - DLC 1,3 | E154: 4.99 | F154: =E154*(1-G154) -> 3.7425 | G154: 0.25
A155: 46268 | B155: 46279 | C155: Publisher Sales | D155: Warhammer 40,000: Space Marine 2 - OST | E155: 6.99 | F155: =E155*(1-G155) -> 5.2425 | G155: 0.25
A156: 46268 | B156: 46279 | C156: Publisher Sales | D156: Warhammer 40,000: Space Marine 2 - Artbook | E156: 7.99 | F156: =E156*(1-G156) -> 5.9925 | G156: 0.25
A157: 46268 | B157: 46279 | C157: Publisher Sales | D157: Warhammer 40,000: Space Marine 2 - DLC 4 (Dark Angels) | E157: 9.99 | F157: =E157*(1-G157) -> 7.4925 | G157: 0.25
A158: 46268 | B158: 46279 | C158: Publisher Sales | D158: Warhammer 40,000: Space Marine 2 - DLC 8 (Salamanders) | E158: 7.99 | F158: =E158*(1-G158) -> 5.9925 | G158: 0.25
A159: 46268 | B159: 46279 | C159: Publisher Sales | D159: Warhammer 40,000: Space Marine 2 - DLC 7 (Raven Guard) | E159: 4.99 | F159: =E159*(1-G159) -> 3.7425 | G159: 0.25
... A165: 46268 | B165: 46279 | C165: Publisher Sales | D165: Warhammer 40,000: Space Marine 2 - DLC 15 (Blood Angels champion) | E165: 7.99 | F165: =E165*(1-G165) -> 5.9925 | G165: 0.25
A166: 46268 | B166: 46279 | C166: Publisher Sales | D166: Warhammer 40,000: Space Marine 2 - DLC 17 (Carcharodons cosmectic) | E166: 4.99 | F166: =E166*(1-G166) -> 3.7425 | G166: 0.25 | H166: Feb
A167: 46268 | B167: 46279 | C167: Publisher Sales | D167: Warhammer 40,000: Space Marine 2 - DLC 16 (Raven guards) | E167: 7.99 | F167: =E167*(1-G167) -> 5.9925 | G167: 0.25 | H167: Feb
A168: 46268 | B168: 46279 | C168: Publisher Sales | D168: Warhammer 40,000: Space Marine 2 - DLC 18 (Iron Hands) | E168: 9.99 | F168: =E168*(1-G168) -> 7.4925 | G168: 0.25 | H168: May
A169: 46268 | B169: 46279 | C169: Publisher Sales | D169: Warhammer 40,000: Space Marine 2 - DLC 19 (Champion Pack 2) | E169: 7.99 | F169: =E169*(1-G169) -> 7.99 | G169: 0 | H169: July
A170: 46268 | B170: 46279 | C170: Publisher Sales | D170: Warhammer 40,000: Space Marine 2 - DLC 20 (Raptors cosmoetic pack) | E170: 4.99 | F170: =E170*(1-G170) -> 4.99 | G170: 0 | H170: July
A172: 46296 | B172: 46303 | C172: Autumn Sales | D172: Warhammer 40,000: Space Marine 2 | E172: 59.99 | F172: =E172*(1-G172) -> 17.997 | G172: 0.7
A173: 46296 | B173: 46303 | C173: Autumn Sales | D173: Warhammer 40,000: Space Marine 2 1 Year Anniversary | E173: 89.99 | F173: =E173*(1-G173) -> 26.997 | G173: 0.7
A174: 46296 | B174: 46303 | C174: Autumn Sales | D174: Warhammer 40,000: Space Marine 2 Ultra Edition | E174: 99.99 | F174: =E174*(1-G174) -> 49.995 | G174: 0.5
...

Sheet RoadCraft 2026
A1: 2026
A2: Start Date | B2: End Date | C2: Program | D2: Content Name | E2: Current SRP ($USD) | F2: Promo SRP ($USD) | G2: Discount %
A3: STEAM
A4: 46030 | B4: 46044 | C4: Custom Sales | D4: Roadcraft | E4: 39.99 | F4: =E4*(1-G4) -> 27.993 | G4: 0.3
A5: 46030 | B5: 46044 | C5: Custom Sales | D5: RoadCraft – Rebuild Edition | E5: 49.99 | F5: =E5*(1-G5) -> 32.4935 | G5: 0.35
A6: 46030 | B6: 46044 | C6: Custom Sales | D6: RoadCraft – Rebuild Expansion | E6: 14.99 | F6: =E6*(1-G6) -> 14.99 | G6: 0
A8: 46074 | B8: 46088 | C8: Custom Sales | D8: Roadcraft | E8: 39.99 | F8: =E8*(1-G8) -> 25.9935 | G8: 0.35 | H8: tbc
A9: 46074 | B9: 46088 | C9: Custom Sales | D9: RoadCraft – Rebuild Edition | E9: 49.99 | F9: =E9*(1-G9) -> 29.994 | G9: 0.4 | H9: tbc
A10: 46074 | B10: 46088 | C10: Custom Sales | D10: RoadCraft – Rebuild Expansion | E10: 14.99 | F10: =E10*(1-G10) -> 14.99 | G10: 0 | H10: tbc
A12: 46100 | B12: 46107 | C12: Spring Sales | D12: Roadcraft | E12: 39.99 | F12: =E12*(1-G12) -> 25.9935 | G12: 0.35
A13: 46100 | B13: 46107 | C13: Spring Sales | D13: RoadCraft – Rebuild Edition | E13: 49.99 | F13: =E13*(1-G13) -> 29.994 | G13: 0.4
A14: 46100 | B14: 46107 | C14: Spring Sales | D14: RoadCraft – Rebuild Expansion | E14: 14.99 | F14: =E14*(1-G14) -> 11.992 | G14: 0.2
A16: 46118 | B16: 46132 | C16: Custom Sales | D16: Roadcraft | E16: 39.99 | F16: =E16*(1-G16) -> 25.9935 | G16: 0.35
A17: 46118 | B17: 46132 | C17: Custom Sales | D17: 1 Year Anniversary Edition | E17: 59.99 | F17: =E17*(1-G17) -> 59.99 | G17: 0
A18: 46118 | B18: 46132 | C18: Custom Sales | D18: Year 1 Pass | E18: 24.99 | F18: =E18*(1-G18) -> 24.99 | G18: 0
A19: 46118 | B19: 46132 | C19: Custom Sales | D19: RoadCraft – Rebuild Expansion | E19: 14.99 | F19: =E19*(1-G19) -> 14.99 | G19: 0
A20: 46118 | B20: 46132 | C20: Custom Sales | D20: RoadCraft – Reclaim Expansion | E20: 14.99 | F20: =E20*(1-G20) -> 14.99 | G20: 0
A22: 46162 | B22: 46176 | C22: Custom Sales | D22: Roadcraft | E22: 39.99 | F22: =E22*(1-G22) -> 23.994 | G22: 0.4
A23: 46162 | B23: 46176 | C23: Custom Sales | D23: 1 Year Anniversary Edition | E23: 59.99 | F23: =E23*(1-G23) -> 44.9925 | G23: 0.25
A24: 46162 | B24: 46176 | C24: Custom Sales | D24: Year 1 Pass | E24: 24.99 | F24: =E24*(1-G24) -> 24.99 | G24: 0
A25: 46162 | B25: 46176 | C25: Custom Sales | D25: RoadCraft – Rebuild Expansion | E25: 14.99 | F25: =E25*(1-G25) -> 11.992 | G25: 0.2
... A51: 46296 | B51: 46303 | C51: Autumn Sales | D51: RoadCraft – Reclaim Expansion | E51: 14.99 | F51: =E51*(1-G51) -> 14.99 | G51: 0
A56: MICROSOFT
A57: 46035 | B57: 46041 | C57: Deals with Game Pass | D57: RoadCraft – Rebuild Edition | E57: $49,99 | F57: $32,49 | G57: 0.35
A58: 46056 | B58: 46069 | C58: Publisher Dedicated Sale | D58: Roadcraft | E58: $39,99 | F58: $27,99 | G58: 0.3
A59: 46086 | B59: 46092 | C59: Best Rated Sale | D59: RoadCraft - Rebuild Edition | E59: $49,99 | F59: $29,99 | G59: 0.4
A60: 46107 | B60: 46113 | C60: Game Pass Spring Sale Review | D60: Roadcraft | E60: $39,99 | F60: $25,99 | G60: 0.35
A61: 46114 | B61: 46127 | C61: Spring Sale | D61: Roadcraft | E61: $39,99 | F61: $25,99 | G61: 0.35
A62: 46126 | B62: 46132 | C62: Deals With Game Pass Ultimate and Core | D62: RoadCraft - Rebuild Edition | E62: $49,99 | F62: $29,99 | G62: 0.4
A63: 46161 | B63: 46167 | C63: Deals With Game Pass Ultimate and Core | D63: RoadCraft – 1-Year Anniversary Edition | E63: 59.99 | F63: 44.99 | G63: 0.25
A64: 46170 | B64: 46183 | C64: Deals Unlocked Sale | D64: Roadcraft | E64: $39,99 | F64: $25,99 | G64: 0.4
A65: 46184 | B65: 46190 | C65: Deals Unlocked Add-on Sale | D65: RoadCraft – Aramatsu Bowhead 20T | E65: $3,99 | F65: $3,19 | G65: 0.2
A66: 46184 | B66: 46190 | C66: Deals Unlocked Add-on Sale | D66: RoadCraft – Reclaim Expansion | E66: $14,99 | F66: $11,99 | G66: 0.2
A67: 46212 | B67: 46219 | C67: Game Pass UGS Teaser Sale | D67: RoadCraft – 1-Year Anniversary Edition | E67: $59,99 | F67: $44,99 | G67: 0.25
A68: 46218 | B68: 46233 | C68: Ultimate Games Sale (UGS) | D68: RoadCraft – 1-Year Anniversary Edition | E68: $59,99 | F68: $44,99 | G68: 0.25
A69: 46231 | B69: 46237 | C69: Deals With Game Pass Ultimate and Core | D69: Roadcraft | E69: $39,99 | F69: $23,99 | G69: 0.4
A70: 46233 | B70: 46247 | C70: UGS Add-on Sale | D70: RoadCraft – Aramatsu Bowhead 20T | E70: $3,99 | F70: $3,19 | G70: 0.2
A71: 46233 | B71: 46247 | C71: UGS Add-on Sale | D71: RoadCraft – Reclaim Expansion | E71: $14,99 | F71: $11,99 | G71: 0.2
A72: 46275 | B72: 46289 | C72: Publisher Spotlight Series | D72: Roadcraft | E72: $39,99 | F72: $23,99 | G72: 0.4
A73: 46275 | B73: 46289 | C73: Publisher Spotlight Series | D73: RoadCraft – 1-Year Anniversary Edition | E73: $59,99 | F73: $44,99 | G73: 0.25
...

Sheet Toxic Commando 2026
A1: 2026
A2: Start Date | B2: End Date | C2: Program | D2: Content Name | E2: Current SRP ($USD) | F2: Promo SRP ($USD) | G2: Discount %
A3: STEAM
A6: 46143 | B6: 46150 | C6: Custom Sales | D6: Base Game | E6: 39.99 | F6: =E6*(1-G6) -> 31.992 | G6: 0.2
A7: 46143 | B7: 46150 | C7: Custom Sales | D7: Blood Edition | E7: 49.99 | F7: =E7*(1-G7) -> 37.4925 | G7: 0.25
A8: 46143 | B8: 46150 | C8: Custom Sales | D8: Bloody Pass | E8: 12.99 | F8: =E8*(1-G8) -> 12.99 | G8: 0
A9: 46143 | B9: 46150 | C9: Custom Sales | D9: DLCs | E9: 14.99 | F9: =E9*(1-G9) -> 11.992 | G9: 0.2
A11: 46181 | B11: 46188 | C11: Custom Sales | D11: Base Game | E11: 39.99 | F11: =E11*(1-G11) -> 31.992 | G11: 0.2
A12: 46181 | B12: 46188 | C12: Custom Sales | D12: Blood Edition | E12: 49.99 | F12: =E12*(1-G12) -> 37.4925 | G12: 0.25
A13: 46181 | B13: 46188 | C13: Custom Sales | D13: Bloody Pass | E13: 12.99 | F13: =E13*(1-G13) -> 12.99 | G13: 0
A14: 46181 | B14: 46188 | C14: Custom Sales | D14: DLCs | E14: 14.99 | F14: =E14*(1-G14) -> 11.992 | G14: 0.2
A16: 46198 | B16: 46212 | C16: Summer Sales | D16: Base Game | E16: 39.99 | F16: =E16*(1-G16) -> 29.9925 | G16: 0.25
A17: 46198 | B17: 46212 | C17: Summer Sales | D17: Blood Edition | E17: 49.99 | F17: =E17*(1-G17) -> 34.993 | G17: 0.3
A18: 46198 | B18: 46212 | C18: Summer Sales | D18: Bloody Pass | E18: 12.99 | F18: =E18*(1-G18) -> 12.99 | G18: 0
A19: 46198 | B19: 46212 | C19: Summer Sales | D19: DLCs | E19: 14.99 | F19: =E19*(1-G19) -> 11.992 | G19: 0.2
... A34: 46296 | B34: 46303 | C34: Autumn Sales | D34: DLCs | E34: 14.99 | F34: =E34*(1-G34) -> 11.992 | G34: 0.2
A36: MICROSOFT
A37: 46143 | B37: 46150 | C37: Custom Sales | D37: Base Game | E37: 39.99 | F37: =E37*(1-G37) -> 31.992 | G37: 0.2
A38: 46143 | B38: 46150 | C38: Custom Sales | D38: Blood Edition | E38: 49.99 | F38: =E38*(1-G38) -> 37.4925 | G38: 0.25
A39: 46143 | B39: 46150 | C39: Custom Sales | D39: Bloody Pass | E39: 12.99 | F39: =E39*(1-G39) -> 12.99 | G39: 0
A40: 46143 | B40: 46150 | C40: Custom Sales | D40: DLCs | E40: 14.99 | F40: =E40*(1-G40) -> 11.992 | G40: 0.2
A41: 46212 | B41: 46219 | C41: Game Pass UGS Teaser Sale | D41: John Carpenter's Toxic Commando | E41: $39,99 | F41: $29,99 | G41: 0.25
A42: 46218 | B42: 46233 | C42: Ultimate Games Sale (UGS) | D42: John Carpenter's Toxic Commando | E42: $39,99 | F42: $29,99 | G42: 0.25
A43: 46238 | B43: 46244 | C43: Deals With Game Pass Ultimate and Core | D43: John Carpenter's Toxic Commando - Blood Edition | E43: $49,99 | F43: $34,99 | G43: 0.3
A44: 46275 | B44: 46289 | C44: Publisher Spotlight Series | D44: John Carpenter's Toxic Commando | E44: $39,99 | F44: $29,99 | G44: 0.25
A45: 46275 | B45: 46289 | C45: Publisher Spotlight Series | D45: John Carpenter's Toxic Commando - Blood Edition | E45: $49,99 | F45: $34,99 | G45: 0.3
A46: 46317 | B46: 46331 | C46: Shocktober Sale | D46: John Carpenter's Toxic Commando - Blood Edition | E46: $49,99 | F46: $34,99 | G46: 0.3
A47: 46345 | B47: 46359 | C47: Black Friday Sale | D47: John Carpenter's Toxic Commando | E47: $39,99 | F47: $29,99 | G47: 0.25
A48: 46364 | B48: 46370 | C48: Deals With Game Pass Ultimate and Core | D48: John Carpenter's Toxic Commando - Blood Edition | E48: $49,99 | F48: $34,99 | G48: 0.3
A49: 46372 | B49: 46029 | C49: Countdown Sale | D49: John Carpenter's Toxic Commando | E49: $39,99 | F49: $29,99 | G49: 0.25
A52: SONY
A53: 46143 | B53: 46150 | C53: Custom Sales | D53: Base Game | E53: 39.99 | F53: =E53*(1-G53) -> 31.992 | G53: 0.2
A54: 46143 | B54: 46150 | C54: Custom Sales | D54: Blood Edition | E54: 49.99 | F54: =E54*(1-G54) -> 37.4925 | G54: 0.25
A55: 46143 | B55: 46150 | C55: Custom Sales | D55: Bloody Pass | E55: 12.99 | F55: =E55*(1-G55) -> 12.99 | G55: 0
A56: 46143 | B56: 46150 | C56: Custom Sales | D56: DLCs | E56: 14.99 | F56: =E56*(1-G56) -> 11.992 | G56: 0.2
A57: 46213 | B57: 46232 | C57: Summer Sale Part 1 | D57: Base Game | E57: 39.99 | F57: =E57*(1-G57) -> 29.9925 | G57: 0.25
A58: 46230 | B58: 46246 | C58: Summer Sale Part 2 | D58: Blood Edition | E58: 49.99 | F58: =E58*(1-G58) -> 34.993 | G58: 0.3
A59: 46260 | B59: 46274 | C59: Gamescom | D59: Base Game | E59: 39.99 | F59: =E59*(1-G59) -> 29.9925 | G59: 0.25
A60: 46274 | B60: 46288 | C60: Tokyo Game Show | D60: Blood Edition | E60: 49.99 | F60: =E60*(1-G60) -> 34.993 | G60: 0.3
A61: TBC | B61: TBC | C61: TBC | D61: Base Game | E61: 39.99 | F61: =E61*(1-G61) -> 29.9925 | G61: 0.25

Sheet Snow 2026
A1: 2026
A2: Start Date | B2: End Date | C2: Program | D2: Content Name | E2: Current SRP ($USD) | F2: Promo SRP ($USD) | G2: Discount % | H2: Release
A3: STEAM
A4: 46044 | B4: 46058 | C4: Custom Sales | D4: SnowRunner | E4: 29.99 | F4: =E4*(1-G4) -> 11.996 | G4: 0.6
A5: 46044 | B5: 46058 | C5: Custom Sales | D5: SnowRunner - 1 year anniversary | E5: 39.99 | F5: =E5*(1-G5) -> 15.996 | G5: 0.6
A6: 46044 | B6: 46058 | C6: Custom Sales | D6: SnowRunner - 2 year anniversary | E6: 64.77 | F6: =E6*(1-G6) -> 34.9758 | G6: 0.46
A7: 46044 | B7: 46058 | C7: Custom Sales | D7: SnowRunner - 3 year anniversary | E7: 84.99 | F7: =E7*(1-G7) -> 50.994 | G7: 0.4
A8: 46044 | B8: 46058 | C8: Custom Sales | D8: SnowRunner - 4 year anniversary | E8: 104.99 | F8: =E8*(1-G8) -> 75.5928 | G8: 0.28
A9: 46044 | B9: 46058 | C9: Custom Sales | D9: SnowRunner - 5 year anniversary | E9: 123.95 | F9: =E9*(1-G9) -> 99.16 | G9: 0.2
A10: 46044 | B10: 46058 | C10: Custom Sales | D10: Snowrunner all seasons except before 12 | E10: 6.99 | F10: =E10*(1-G10) -> 4.5435 | G10: 0.35
A11: 46044 | B11: 46058 | C11: Custom Sales | D11: Season 12 | E11: 11.99 | F11: =E11*(1-G11) -> 7.7935 | G11: 0.35
A12: 46044 | B12: 46058 | C12: Custom Sales | D12: Season 13 | E12: 6.99 | F12: =E12*(1-G12) -> 4.5435 | G12: 0.35
A13: 46044 | B13: 46058 | C13: Custom Sales | D13: Season 14 | E13: 6.99 | F13: =E13*(1-G13) -> 4.893 | G13: 0.3
A14: 46044 | B14: 46058 | C14: Custom Sales | D14: Season 15 | E14: 6.99 | F14: =E14*(1-G14) -> 5.2425 | G14: 0.25
A15: 46044 | B15: 46058 | C15: Custom Sales | D15: Season 16 | E15: 6.99 | F15: =E15*(1-G15) -> 5.592 | G15: 0.2
... A21: 46044 | B21: 46058 | C21: Custom Sales | D21: SnowRunner Year 5 Pass | E21: 24.99 | F21: =E21*(1-G21) -> 24.99 | G21: 0
A23: 46088 | B23: 46100 | C23: Custom Sales | D23: SnowRunner | E23: 29.99 | F23: =E23*(1-G23) -> 11.996 | G23: 0.6 | H23: TBC
A24: 46088 | B24: 46100 | C24: Custom Sales | D24: SnowRunner - 1 year anniversary | E24: 39.99 | F24: =E24*(1-G24) -> 15.996 | G24: 0.6 | H24: TBC
A25: 46088 | B25: 46100 | C25: Custom Sales | D25: SnowRunner - 2 year anniversary | E25: 64.77 | F25: =E25*(1-G25) -> 34.9758 | G25: 0.46 | H25: TBC
A26: 46088 | B26: 46100 | C26: Custom Sales | D26: SnowRunner - 3 year anniversary | E26: 84.99 | F26: =E26*(1-G26) -> 50.994 | G26: 0.4 | H26: TBC
A27: 46088 | B27: 46100 | C27: Custom Sales | D27: SnowRunner - 4 year anniversary | E27: 104.99 | F27: =E27*(1-G27) -> 75.5928 | G27: 0.28 | H27: TBC
A28: 46088 | B28: 46100 | C28: Custom Sales | D28: SnowRunner - 5 year anniversary | E28: 123.95 | F28: =E28*(1-G28) -> 99.16 | G28: 0.2 | H28: TBC
A29: 46088 | B29: 46100 | C29: Custom Sales | D29: Snowrunner all seasons except before 12 | E29: 6.99 | F29: =E29*(1-G29) -> 4.5435 | G29: 0.35
A30: 46088 | B30: 46100 | C30: Custom Sales | D30: Season 12 | E30: 11.99 | F30: =E30*(1-G30) -> 7.7935 | G30: 0.35
A31: 46088 | B31: 46100 | C31: Custom Sales | D31: Season 13 | E31: 6.99 | F31: =E31*(1-G31) -> 4.5435 | G31: 0.35
A32: 46088 | B32: 46100 | C32: Custom Sales | D32: Season 14 | E32: 6.99 | F32: =E32*(1-G32) -> 4.893 | G32: 0.3
A33: 46088 | B33: 46100 | C33: Custom Sales | D33: Season 15 | E33: 6.99 | F33: =E33*(1-G33) -> 5.2425 | G33: 0.25
A34: 46088 | B34: 46100 | C34: Custom Sales | D34: Season 16 | E34: 6.99 | F34: =E34*(1-G34) -> 5.592 | G34: 0.2
A35: 46088 | B35: 46100 | C35: Custom Sales | D35: Snowrunner all Vehicules | E35: 3.99 | F35: =E35*(1-G35) -> 3.192 | G35: 0.2
A36: 46088 | B36: 46100 | C36: Custom Sales | D36: SnowRunner Year 1 Pass | E36: 24.99 | F36: =E36*(1-G36) -> 17.493 | G36: 0.3
A37: 46088 | B37: 46100 | C37: Custom Sales | D37: SnowRunner Year 2 Pass | E37: 24.99 | F37: =E37*(1-G37) -> 17.493 | G37: 0.3
A38: 46088 | B38: 46100 | C38: Custom Sales | D38: SnowRunner Year 3 Pass | E38: 24.99 | F38: =E38*(1-G38) -> 18.7425 | G38: 0.25
A39: 46088 | B39: 46100 | C39: Custom Sales | D39: SnowRunner Year 4 Pass | E39: 24.99 | F39: =E39*(1-G39) -> 19.992 | G39: 0.2
A40: 46088 | B40: 46100 | C40: Custom Sales | D40: SnowRunner Year 5 Pass | E40: 24.99 | F40: =E40*(1-G40) -> 24.99 | G40: 0
... A157: 46296 | B157: 46303 | C157: Autumn Sales | D157: SnowRunner Year 5 Pass | E157: 24.99 | F157: =E157*(1-G157) -> 19.992 | G157: 0.2
A160: MICROSOFT
A161: 46030 | B161: 46043 | C161: Countdown Add-on Sale | D161: SnowRunner - Season 1: Search & Recover | E161: $6,99 | F161: $4,54 | G161: 0.35
A162: 46030 | B162: 46043 | C162: Countdown Add-on Sale | D162: SnowRunner - Season 2: Explore & Expand | E162: $6,99 | F162: $4,54 | G162: 0.35
A163: 46030 | B163: 46043 | C163: Countdown Add-on Sale | D163: SnowRunner - Season 3: Locate & Deliver | E163: $6,99 | F163: $4,54 | G163: 0.35
A164: 46030 | B164: 46043 | C164: Countdown Add-on Sale | D164: SnowRunner - Season 4: New Frontiers | E164: $11,99 | F164: $7,79 | G164: 0.35
...

Sheet Expe 2026
A1: 2026
A2: Start Date | B2: End Date | C2: Program | D2: Content Name | E2: Current SRP ($USD) | F2: Promo SRP ($USD) | G2: Discount %
A3: STEAM
A4: 46030 | B4: 46044 | C4: Custom Sales | D4: Expeditions Base Game | E4: 39.99 | F4: =E4*(1-G4) -> 17.9955 | G4: 0.55
A5: 46030 | B5: 46044 | C5: Custom Sales | D5: Expeditions Year 1 Edition | E5: 59.99 | F5: =E5*(1-G5) -> 26.9955 | G5: 0.55
A6: 46030 | B6: 46044 | C6: Custom Sales | D6: Expeditions Supreme Edition | E6: 69.99 | F6: =E6*(1-G6) -> 31.4955 | G6: 0.55
A7: 46030 | B7: 46044 | C7: Custom Sales | D7: Expeditions Year 1 pass | E7: 29.99 | F7: =E7*(1-G7) -> 22.4925 | G7: 0.25
A8: 46030 | B8: 46044 | C8: Custom Sales | D8: Expeditions Pioneer pack | E8: 11.99 | F8: =E8*(1-G8) -> 8.9925 | G8: 0.25
A9: 46030 | B9: 46044 | C9: Custom Sales | D9: Expeditions the Great Don 71 | E9: 2.99 | F9: =E9*(1-G9) -> 2.392 | G9: 0.2
A10: 46030 | B10: 46044 | C10: Custom Sales | D10: Expeditions cotto canyon | E10: 2.99 | F10: =E10*(1-G10) -> 2.392 | G10: 0.2
A11: 46030 | B11: 46044 | C11: Custom Sales | D11: Saison 1 | E11: 6.99 | F11: =E11*(1-G11) -> 5.2425 | G11: 0.25
A12: 46030 | B12: 46044 | C12: Custom Sales | D12: Saison 2 | E12: 6.99 | F12: =E12*(1-G12) -> 5.592 | G12: 0.2
A13: 46030 | B13: 46044 | C13: Custom Sales | D13: Saison 3 | E13: 6.99 | F13: =E13*(1-G13) -> 5.592 | G13: 0.2
A14: 46030 | B14: 46044 | C14: Custom Sales | D14: Saison 4 | E14: 6.99 | F14: =E14*(1-G14) -> 6.99 | G14: 0
A16: 46074 | B16: 46088 | C16: Custom Sales | D16: Expeditions Base Game | E16: 39.99 | F16: =E16*(1-G16) -> 17.9955 | G16: 0.55
... A110: 46296 | B110: 46303 | C110: Autumn Sales | D110: Saison 4 | E110: 6.99 | F110: =E110*(1-G110) -> 5.592 | G110: 0.2
A115: MICROSOFT
A116: 46030 | B116: 46043 | C116: Countdown Add-on Sale | D116: Expeditions: A MudRunner game - Season 1: Cave Odyssey | E116: $6,99 | F116: $5,24 | G116: 0.25
A117: 46030 | B117: 46043 | C117: Countdown Add-on Sale | D117: Expeditions: A MudRunner Game - Season 2: White Dawn | E117: $7,99 | F117: $5,99 | G117: 0.25
A118: 46030 | B118: 46043 | C118: Countdown Add-on Sale | D118: Expeditions: A MudRunner Game - Season 3: Icy Shores | E118: $7,99 | F118: $6,39 | G118: 0.2
A119: 46030 | B119: 46043 | C119: Countdown Add-on Sale | D119: Expeditions: A MudRunner game - Season 1: Cave Odyssey | E119: $6,99 | F119: $5,24 | G119: 0.25
A120: 46030 | B120: 46043 | C120: Countdown Add-on Sale | D120: Expeditions: A MudRunner Game - Season 2: White Dawn | E120: $7,99 | F120: $5,99 | G120: 0.25
A121: 46030 | B121: 46043 | C121: Countdown Add-on Sale | D121: Expeditions: A MudRunner Game - Season 3: Icy Shores | E121: $7,99 | F121: $6,39 | G121: 0.2
A122: 46035 | B122: 46041 | C122: Deals with Game Pass | D122: Expeditions: A MudRunner Game - Supreme Edition | E122: $79,99 | F122: $40,00 | G122: 0.5
A123: 46035 | B123: 46041 | C123: Deals with Game Pass | D123: Expeditions: A MudRunner Game - Supreme Edition | E123: $69,99 | F123: $35,00 | G123: 0.5
A124: 46056 | B124: 46069 | C124: Publisher Dedicated Sale | D124: Expeditions: A MudRunner Game | E124: $49,99 | F124: $20,00 | G124: 0.6
A125: 46056 | B125: 46069 | C125: Publisher Dedicated Sale | D125: Expeditions: A MudRunner Game | E125: $39,99 | F125: $16,00 | G125: 0.6
A126: 46077 | B126: 46083 | C126: Opportunistic | D126: Expeditions: A MudRunner game - Season 1: Cave Odyssey | E126: $6,99 | F126: $5,24 | G126: 0.25
A127: 46077 | B127: 46083 | C127: Opportunistic | D127: Expeditions: A MudRunner Game - Season 2: White Dawn | E127: $7,99 | F127: $5,99 | G127: 0.25
... A151: 46184 | B151: 46190 | C151: Deals Unlocked Add-on Sale | D151: Expeditions: A MudRunner Game - Season 2: White Dawn | E151: $7,99 | F151: $5,99 | G151: 0.25
A152: 46184 | B152: 46190 | C152: Deals Unlocked Add-on Sale | D152: Expeditions: A MudRunner Game - Season 3: Icy Shores | E152: $7,99 | F152: 5.99 | G152: 0.25
A153: 46184 | B153: 46190 | C153: Deals Unlocked Add-on Sale | D153: Expeditions: A MudRunner game - Season 1: Cave Odyssey | E153: $6,99 | F153: $5,24 | G153: 0.25
A154: 46184 | B154: 46190 | C154: Deals Unlocked Add-on Sale | D154: Expeditions: A MudRunner Game - Season 2: White Dawn | E154: $7,99 | F154: $5,99 | G154: 0.25
A155: 46184 | B155: 46190 | C155: Deals Unlocked Add-on Sale | D155: Expeditions: A MudRunner Game - Season 3: Icy Shores | E155: $7,99 | F155: 5.99 | G155: 0.25
A156: 46191 | B156: 46204 | C156: Simulator Sale | D156: Expeditions: A MudRunner Game - Supreme Edition | E156: $79,99 | F156: $32,00 | G156: 0.6
A157: 46191 | B157: 46204 | C157: Simulator Sale | D157: Expeditions: A MudRunner Game - Supreme Edition | E157: $69,99 | F157: $28,00 | G157: 0.6
A158: 46210 | B158: 46216 | C158: Deals With Game Pass Ultimate and Core | D158: Expeditions: A MudRunner Game - Year 1 Edition | E158: $69,99 | F158: $28,00 | G158: 0.6
A159: 46210 | B159: 46216 | C159: Deals With Game Pass Ultimate and Core | D159: Expeditions: A MudRunner Game - Year 1 Edition (Windows) | E159: $59,99 | F159: $24,00 | G159: 0.6
A160: 46210 | B160: 46216 | C160: Opportunistic | D160: Expeditions: A MudRunner Game - Year 1 Pass | E160: $29,99 | F160: $19,49 | G160: 0.35
A161: 46210 | B161: 46216 | C161: Opportunistic | D161: Expeditions: A MudRunner Game - Year 1 Pass (Windows) | E161: $29,99 | F161: $19,49 | G161: 0.35
...

Sheet ISS 2026
A1: 2026
A2: Start Date | B2: End Date | C2: Program | D2: Content Name | E2: Current SRP ($USD) | F2: Promo SRP ($USD) | G2: Discount %
A3: STEAM
A4: 46030 | B4: 46044 | C4: Custom Sales | D4: Insurgency Sandstorm | E4: 29.99 | F4: =E4*(1-G4) -> 8.997 | G4: 0.7
A5: 46030 | B5: 46044 | C5: Custom Sales | D5: Insurgency Sandstorm 1 Year Anniversary | E5: 39.99 | F5: =E5*(1-G5) -> 9.9975 | G5: 0.75
A6: 46030 | B6: 46044 | C6: Custom Sales | D6: Insurgency Sandstorm Gold Edition | E6: 59.99 | F6: =E6*(1-G6) -> 17.997 | G6: 0.7
A7: 46030 | B7: 46044 | C7: Custom Sales | D7: Insurgency Sandstorm Ultimate Edition | E7: 69.99 | F7: =E7*(1-G7) -> 34.995 | G7: 0.5
A8: 46030 | B8: 46044 | C8: Custom Sales | D8: Insurgency Sandstorm 4 Year Anniversary | E8: 89.99 | F8: =E8*(1-G8) -> 40.4955 | G8: 0.55
A9: 46030 | B9: 46044 | C9: Custom Sales | D9: Insurgency Sandstorm Year Pass 1 | E9: 24.99 | F9: =E9*(1-G9) -> 12.495 | G9: 0.5
A10: 46030 | B10: 46044 | C10: Custom Sales | D10: Insurgency Sandstorm Year Pass 2 | E10: 29.99 | F10: =E10*(1-G10) -> 14.995 | G10: 0.5
A11: 46030 | B11: 46044 | C11: Custom Sales | D11: Insurgency Sandstorm Year Pass 3 | E11: 34.99 | F11: =E11*(1-G11) -> 24.493 | G11: 0.3
A12: 46030 | B12: 46044 | C12: Custom Sales | D12: Insurgency Sandstorm Year Pass 4 | E12: 34.99 | F12: =E12*(1-G12) -> 34.99 | G12: 0
A13: 46030 | B13: 46044 | C13: Custom Sales | D13: Insurgency Sandstorm Year Pass 1 + 2 | E13: 44.99 | F13: =E13*(1-G13) -> 22.495 | G13: 0.5
A14: 46030 | B14: 46044 | C14: Custom Sales | D14: Insurgency Sandstorm Year Pass 1 + 2+3+4 | E14: 59.99 | F14: =E14*(1-G14) -> 44.9925 | G14: 0.25
A16: 46074 | B16: 46088 | C16: Custom Sales | D16: Insurgency Sandstorm | E16: 29.99 | F16: =E16*(1-G16) -> 7.4975 | G16: 0.75 | H16: TBC
A17: 46074 | B17: 46088 | C17: Custom Sales | D17: Insurgency Sandstorm 1 Year Anniversary | E17: 39.99 | F17: =E17*(1-G17) -> 9.9975 | G17: 0.75
A18: 46074 | B18: 46088 | C18: Custom Sales | D18: Insurgency Sandstorm Gold Edition | E18: 59.99 | F18: =E18*(1-G18) -> 17.997 | G18: 0.7
A19: 46074 | B19: 46088 | C19: Custom Sales | D19: Insurgency Sandstorm Ultimate Edition | E19: 69.99 | F19: =E19*(1-G19) -> 34.995 | G19: 0.5
A20: 46074 | B20: 46088 | C20: Custom Sales | D20: Insurgency Sandstorm 4 Year Anniversary | E20: 89.99 | F20: =E20*(1-G20) -> 40.4955 | G20: 0.55
A21: 46074 | B21: 46088 | C21: Custom Sales | D21: Insurgency Sandstorm Year Pass 1 | E21: 24.99 | F21: =E21*(1-G21) -> 12.495 | G21: 0.5
A22: 46074 | B22: 46088 | C22: Custom Sales | D22: Insurgency Sandstorm Year Pass 2 | E22: 29.99 | F22: =E22*(1-G22) -> 14.995 | G22: 0.5
A23: 46074 | B23: 46088 | C23: Custom Sales | D23: Insurgency Sandstorm Year Pass 3 | E23: 34.99 | F23: =E23*(1-G23) -> 24.493 | G23: 0.3
A24: 46074 | B24: 46088 | C24: Custom Sales | D24: Insurgency Sandstorm Year Pass 4 | E24: 34.99 | F24: =E24*(1-G24) -> 34.99 | G24: 0
A25: 46074 | B25: 46088 | C25: Custom Sales | D25: Insurgency Sandstorm Year Pass 1 + 2 | E25: 44.99 | F25: =E25*(1-G25) -> 22.495 | G25: 0.5
A26: 46074 | B26: 46088 | C26: Custom Sales | D26: Insurgency Sandstorm Year Pass 1 + 2+3+4 | E26: 59.99 | F26: =E26*(1-G26) -> 44.9925 | G26: 0.25
A28: 46100 | B28: 46107 | C28: Spring Sales | D28: Insurgency Sandstorm | E28: 29.99 | F28: =E28*(1-G28) -> 7.4975 | G28: 0.75
A29: 46100 | B29: 46107 | C29: Spring Sales | D29: Insurgency Sandstorm 1 Year Anniversary | E29: 39.99 | F29: =E29*(1-G29) -> 11.997 | G29: 0.7
... A104: 46296 | B104: 46303 | C104: Autumn Sales | D104: Insurgency Sandstorm Year Pass 1 + 2+3+4 | E104: 59.99 | F104: =E104*(1-G104) -> 44.9925 | G104: 0.25
A109: MICROSOFT
A110: 46030 | B110: 46043 | C110: Countdown Add-on Sale | D110: Insurgency: Sandstorm - Year 1+2 Bundle | E110: $44,99 | F110: $22,50 | G110: 0.5
A111: 46030 | B111: 46043 | C111: Countdown Add-on Sale | D111: Insurgency: Sandstorm - Year 1 Pass | E111: $24,99 | F111: $12,50 | G111: 0.5
A112: 46030 | B112: 46043 | C112: Countdown Add-on Sale | D112: Insurgency: Sandstorm - Year 2 Pass | E112: $29,99 | F112: $15,00 | G112: 0.5
A113: 46030 | B113: 46043 | C113: Countdown Add-on Sale | D113: Insurgency: Sandstorm - Year 3 Pass | E113: $34,99 | F113: $24,49 | G113: 0.3
A114: 46035 | B114: 46041 | C114: Deals with Game Pass | D114: Insurgency Sandstorm Deluxe Edition | E114: $49,99 | F114: $15,00 | G114: 0.7
A115: 46035 | B115: 46041 | C115: Deals with Game Pass | D115: Insurgency Sandstorm Deluxe Edition | E115: $39,99 | F115: $12,00 | G115: 0.7
A116: 46042 | B116: 46048 | C116: Deals with Game Pass | D116: Insurgency: Sandstorm - 4-Year Anniversary Edition | E116: $99,99 | F116: $59,99 | G116: 0.4
A117: 46056 | B117: 46069 | C117: Publisher Dedicated Sale | D117: Insurgency Sandstorm | E117: $39,99 | F117: $12,00 | G117: 0.7
A118: 46056 | B118: 46069 | C118: Publisher Dedicated Sale | D118: Insurgency Sandstorm | E118: $29,99 | F118: $9,00 | G118: 0.7
A119: 46077 | B119: 46083 | C119: Opportunistic | D119: Insurgency: Sandstorm - Year 1+2 Bundle | E119: $44,99 | F119: $18,00 | G119: 0.6
A120: 46077 | B120: 46083 | C120: Opportunistic | D120: Insurgency: Sandstorm - Year 1 Pass | E120: $24,99 | F120: $12,50 | G120: 0.5
...

Sheet SM2 2025
A1: 2025
A2: Start Date | B2: End Date | C2: Program | D2: Content Name | E2: Current SRP ($USD) | F2: Promo SRP ($USD) | G2: Discount %
A3: STEAM
A4: 45673 | B4: 45684 | C4: Weekend Deal extended | D4: Warhammer 40,000: Space Marine 2 | E4: 59.99 | F4: =E4*(1-G4) -> 44.9925 | G4: 0.25
A5: 45673 | B5: 45684 | C5: Weekend Deal extended | D5: Warhammer 40,000: Space Marine 2 Gold Edition | E5: 89.99 | F5: =E5*(1-G5) -> 67.4925 | G5: 0.25
A6: 45673 | B6: 45684 | C6: Weekend Deal extended | D6: Warhammer 40,000: Space Marine 2 Ultra Edition | E6: 99.99 | F6: =E6*(1-G6) -> 74.9925 | G6: 0.25
A7: 45673 | B7: 45684 | C7: Weekend Deal extended | D7: Warhammer 40,000: Space Marine 2 - Season Pass | E7: 39.99 | F7: =E7*(1-G7) -> 31.992 | G7: 0.2 | H7: 45536
A8: 45673 | B8: 45684 | C8: Weekend Deal extended | D8: Warhammer 40,000: Space Marine 2 - DLC 1,3 | E8: 4.99 | F8: =E8*(1-G8) -> 3.992 | G8: 0.2 | H8: 45566
A9: 45673 | B9: 45684 | C9: Weekend Deal extended | D9: Warhammer 40,000: Space Marine 2 - OST | E9: 6.99 | F9: =E9*(1-G9) -> 5.592 | G9: 0.2 | H9: 45566
A10: 45673 | B10: 45684 | C10: Weekend Deal extended | D10: Warhammer 40,000: Space Marine 2 - Artbook | E10: 7.99 | F10: =E10*(1-G10) -> 6.392 | G10: 0.2 | H10: 45566
A11: 45673 | B11: 45684 | C11: Weekend Deal extended | D11: Warhammer 40,000: Space Marine 2 - DLC 4 (Dark Angels) | E11: 9.99 | F11: =E11*(1-G11) -> 9.99 | G11: 0 | H11: Dec 2024
A14: 45721 | B14: 45729 | C14: Custom deal early March | D14: Warhammer 40,000: Space Marine 2 | E14: 59.99 | F14: =E14*(1-G14) -> 38.9935 | G14: 0.35 | H14: TBC
A15: 45721 | B15: 45729 | C15: Custom deal early March | D15: Warhammer 40,000: Space Marine 2 Gold Edition | E15: 89.99 | F15: =E15*(1-G15) -> 58.4935 | G15: 0.35
A16: 45721 | B16: 45729 | C16: Custom deal early March | D16: Warhammer 40,000: Space Marine 2 Ultra Edition | E16: 99.99 | F16: =E16*(1-G16) -> 64.9935 | G16: 0.35
A17: 45721 | B17: 45729 | C17: Custom deal early March | D17: Warhammer 40,000: Space Marine 2 - Season Pass | E17: 39.99 | F17: =E17*(1-G17) -> 31.992 | G17: 0.2 | I17: 45536
A18: 45721 | B18: 45729 | C18: Custom deal early March | D18: Warhammer 40,000: Space Marine 2 - DLC 1,3 | E18: 4.99 | F18: =E18*(1-G18) -> 3.992 | G18: 0.2 | I18: 45566
A19: 45721 | B19: 45729 | C19: Custom deal early March | D19: Warhammer 40,000: Space Marine 2 - OST | E19: 6.99 | F19: =E19*(1-G19) -> 5.592 | G19: 0.2 | I19: 45566
A20: 45721 | B20: 45729 | C20: Custom deal early March | D20: Warhammer 40,000: Space Marine 2 - Artbook | E20: 7.99 | F20: =E20*(1-G20) -> 6.392 | G20: 0.2 | I20: 45566
A21: 45721 | B21: 45729 | C21: Custom deal early March | D21: Warhammer 40,000: Space Marine 2 - DLC 4 (Dark Angels) | E21: 9.99 | F21: =E21*(1-G21) -> 7.992 | G21: 0.2 | I21: Dec 2024
A22: 45721 | B22: 45729 | C22: Custom deal early March | D22: Warhammer 40,000: Space Marine 2 - DLC 8 (Salamanders) | E22: 7.99 | F22: =E22*(1-G22) -> 7.99 | G22: 0 | I22: Feb. 2025
A23: 45721 | B23: 45729 | C23: Custom deal early March | D23: Warhammer 40,000: Space Marine 2 - DLC 7 (Raven Guard) | E23: 4.99 | F23: =E23*(1-G23) -> 4.99 | G23: 0 | I23: Feb. 2025
A25: 45729 | B25: 45734 | C25: Spring Sales | D25: Warhammer 40,000: Space Marine 2 | E25: 59.99 | F25: =E25*(1-G25) -> 38.9935 | G25: 0.35 | H25: TBC
A26: 45729 | B26: 45734 | C26: Spring Sales | D26: Warhammer 40,000: Space Marine 2 Gold Edition | E26: 89.99 | F26: =E26*(1-G26) -> 58.4935 | G26: 0.35
A27: 45729 | B27: 45734 | C27: Spring Sales | D27: Warhammer 40,000: Space Marine 2 Ultra Edition | E27: 99.99 | F27: =E27*(1-G27) -> 64.9935 | G27: 0.35
A28: 45729 | B28: 45734 | C28: Spring Sales | D28: Warhammer 40,000: Space Marine 2 - Season Pass | E28: 39.99 | F28: =E28*(1-G28) -> 31.992 | G28: 0.2 | I28: 45536
A29: 45729 | B29: 45734 | C29: Spring Sales | D29: Warhammer 40,000: Space Marine 2 - DLC 1,3 | E29: 4.99 | F29: =E29*(1-G29) -> 3.992 | G29: 0.2 | I29: 45566
A30: 45729 | B30: 45734 | C30: Spring Sales | D30: Warhammer 40,000: Space Marine 2 - OST | E30: 6.99 | F30: =E30*(1-G30) -> 5.592 | G30: 0.2 | I30: 45566
A31: 45729 | B31: 45734 | C31: Spring Sales | D31: Warhammer 40,000: Space Marine 2 - Artbook | E31: 7.99 | F31: =E31*(1-G31) -> 6.392 | G31: 0.2 | I31: 45566
A32: 45729 | B32: 45734 | C32: Spring Sales | D32: Warhammer 40,000: Space Marine 2 - DLC 4 (Dark Angels) | E32: 9.99 | F32: =E32*(1-G32) -> 7.992 | G32: 0.2 | I32: Dec 2024
A33: 45729 | B33: 45734 | C33: Spring Sales | D33: Warhammer 40,000: Space Marine 2 - DLC 8 (Salamanders) | E33: 7.99 | F33: =E33*(1-G33) -> 7.99 | G33: 0 | I33: Feb. 2025
A34: 45729 | B34: 45734 | C34: Spring Sales | D34: Warhammer 40,000: Space Marine 2 - DLC 7 (Raven Guard) | E34: 4.99 | F34: =E34*(1-G34) -> 4.99 | G34: 0 | I34: Feb. 2025
A36: 45759 | B36: 45769 | C36: Custom Deal pre Skulls | D36: Warhammer 40,000: Space Marine 2 | E36: 59.99 | F36: =E36*(1-G36) -> 38.9935 | G36: 0.35 | H36: TBC
A37: 45759 | B37: 45769 | C37: Custom Deal pre Skulls | D37: Warhammer 40,000: Space Marine 2 Gold Edition | E37: 89.99 | F37: =E37*(1-G37) -> 58.4935 | G37: 0.35
A38: 45759 | B38: 45769 | C38: Custom Deal pre Skulls | D38: Warhammer 40,000: Space Marine 2 Ultra Edition | E38: 99.99 | F38: =E38*(1-G38) -> 64.9935 | G38: 0.35
A39: 45759 | B39: 45769 | C39: Custom Deal pre Skulls | D39: Warhammer 40,000: Space Marine 2 - Season Pass | E39: 39.99 | F39: =E39*(1-G39) -> 31.992 | G39: 0.2 | I39: 45536
A40: 45759 | B40: 45769 | C40: Custom Deal pre Skulls | D40: Warhammer 40,000: Space Marine 2 - DLC 1,3 | E40: 4.99 | F40: =E40*(1-G40) -> 3.992 | G40: 0.2 | I40: 45566
A41: 45759 | B41: 45769 | C41: Custom Deal pre Skulls | D41: Warhammer 40,000: Space Marine 2 - OST | E41: 6.99 | F41: =E41*(1-G41) -> 5.592 | G41: 0.2 | I41: 45566
A42: 45759 | B42: 45769 | C42: Custom Deal pre Skulls | D42: Warhammer 40,000: Space Marine 2 - Artbook | E42: 7.99 | F42: =E42*(1-G42) -> 6.392 | G42: 0.2 | I42: 45566
A43: 45759 | B43: 45769 | C43: Custom Deal pre Skulls | D43: Warhammer 40,000: Space Marine 2 - DLC 4 (Dark Angels) | E43: 9.99 | F43: =E43*(1-G43) -> 7.992 | G43: 0.2 | I43: Dec 2024
A44: 45759 | B44: 45769 | C44: Custom Deal pre Skulls | D44: Warhammer 40,000: Space Marine 2 - DLC 8 (Salamanders) | E44: 7.99 | F44: =E44*(1-G44) -> 7.99 | G44: 0 | I44: Feb. 2025
...

Sheet RoadCraft 2025
A1: 2025
A2: Start Date | B2: End Date | C2: Program | D2: Content Name | E2: Current SRP ($USD) | F2: Promo SRP ($USD) | G2: Discount %
A3: STEAM
A4: 45904 | B4: 45915 | C4: Publisher Sales | D4: Roadcraft | E4: 39.99 | F4: =E4*(1-G4) -> 31.992 | G4: 0.2
A5: 45904 | B5: 45915 | C5: Publisher Sales | D5: RoadCraft – Rebuild Edition | E5: 49.99 | F5: =E5*(1-G5) -> 37.4925 | G5: 0.25
A6: 45904 | B6: 45915 | C6: Publisher Sales | D6: RoadCraft – Rebuild Expansion | E6: 14.99 | F6: =E6*(1-G6) -> 14.99 | G6: 0
A8: 45929 | B8: 45936 | C8: Autumn Sales | D8: Roadcraft | E8: 39.99 | F8: =E8*(1-G8) -> 29.9925 | G8: 0.25
A9: 45929 | B9: 45936 | C9: Autumn Sales | D9: RoadCraft – Rebuild Edition | E9: 49.99 | F9: =E9*(1-G9) -> 34.993 | G9: 0.3
A10: 45929 | B10: 45936 | C10: Autumn Sales | D10: RoadCraft – Rebuild Expansion | E10: 14.99 | F10: =E10*(1-G10) -> 14.99 | G10: 0
A12: 46350 | B12: 46357 | C12: Black Friday | D12: Roadcraft | E12: 39.99 | F12: =E12*(1-G12) -> 27.993 | G12: 0.3
A13: 46350 | B13: 46357 | C13: Black Friday | D13: RoadCraft – Rebuild Edition | E13: 49.99 | F13: =E13*(1-G13) -> 32.4935 | G13: 0.35
A14: 46350 | B14: 46357 | C14: Black Friday | D14: RoadCraft – Rebuild Expansion | E14: 14.99 | F14: =E14*(1-G14) -> 14.99 | G14: 0
A16: 46374 | B16: 46027 | C16: Winter Sales | D16: Roadcraft | E16: 39.99 | F16: =E16*(1-G16) -> 27.993 | G16: 0.3
A17: 46374 | B17: 46027 | C17: Winter Sales | D17: RoadCraft – Rebuild Edition | E17: 49.99 | F17: =E17*(1-G17) -> 32.4935 | G17: 0.35
A18: 46374 | B18: 46027 | C18: Winter Sales | D18: RoadCraft – Rebuild Expansion | E18: 14.99 | F18: =E18*(1-G18) -> 14.99 | G18: 0
A21: MICROSOFT
A22: 45853 | B22: 45859 | C22: Deals With Game Pass Ultimate and Core | D22: Roadcraft | E22: $39,99 | F22: $31,99 | G22: 0.2
A23: 45888 | B23: 45902 | C23: Keep On Gaming Sale | D23: Roadcraft | E23: $39,99 | F23: $31,99 | G23: 0.2
A24: 46302 | B24: 46315 | C24: Publisher Spotlight | D24: Roadcraft | E24: $39,99 | F24: $31,99 | G24: 0.2
A25: 46323 | B25: 46329 | C25: Deals With Game Pass Ultimate and Core | D25: RoadCraft – Rebuild Edition | E25: $49,99 | F25: $37,49 | G25: 0.25
A26: 46346 | B26: 46359 | C26: Black Friday Sale | D26: Roadcraft | E26: $39,99 | F26: $29,99 | G26: 0.25
A27: 46360 | B27: 46373 | C27: Game Pass Games to Gift Sale | D27: RoadCraft – Rebuild Edition | E27: $49,99 | F27: $34,99 | G27: 0.3
A28: 46374 | B28: 46029 | C28: Countdown Sale | D28: Roadcraft | E28: $39,99 | F28: $27,99 | G28: 0.3
A30: SONY
A31: 45854 | B31: 45868 | C31: Summer Sale - Part 1 | D31: RoadCraft | E31: 39.99 | F31: =E31*(1-G31) -> 31.992 | G31: 0.2
A32: 45896 | B32: 45910 | C32: Ready, Set, Play! | D32: RoadCraft | E32: 39.99 | F32: =E32*(1-G32) -> 31.992 | G32: 0.2
A33: 45910 | B33: 45924 | C33: Autumn Adventures | D33: RoadCraft - Rebuild Edition | E33: 49.99 | F33: =E33*(1-G33) -> 39.992 | G33: 0.2
A34: 45938 | B34: 45952 | C34: Player's Choice | D34: RoadCraft | E34: 39.99 | F34: =E34*(1-G34) -> 31.992 | G34: 0.2
A35: 45952 | B35: 45967 | C35: Planet of the Discounts | D35: RoadCraft - Rebuild Edition | E35: 49.99 | F35: =E35*(1-G35) -> 37.4925 | G35: 0.25
A36: 45982 | B36: 45992 | C36: Black Friday | D36: RoadCraft | E36: 39.99 | F36: =E36*(1-G36) -> 29.9925 | G36: 0.25
A37: 45992 | B37: 46007 | C37: End of Year Deals | D37: RoadCraft - Rebuild Edition | E37: 49.99 | F37: =E37*(1-G37) -> 32.4935 | G37: 0.35
A38: 46010 | B38: 46012 | C38: Holiday-Jan Sale - PS+ EA | D38: RoadCraft | E38: 39.99 | F38: =E38*(1-G38) -> 27.993 | G38: 0.3
A39: 46013 | B39: 46029 | C39: Holiday-Jan Sale - Part 1 | D39: RoadCraft | E39: 39.99 | F39: =E39*(1-G39) -> 27.993 | G39: 0.3
A40: 46027 | B40: 46043 | C40: Holiday-Jan Sale - Part 2 | D40: RoadCraft - Rebuild Edition | E40: 49.99 | F40: =E40*(1-G40) -> 32.4935 | G40: 0.35
A41: 46057 | B41: 46078 | C41: LNY/Critic's Choice | D41: RoadCraft | E41: 39.99 | F41: =E41*(1-G41) -> 27.993 | G41: 0.3
A42: 46078 | B42: 46092 | C42: Dealmania | D42: RoadCraft - Rebuild Edition | E42: 49.99 | F42: =E42*(1-G42) -> 32.4935 | G42: 0.35
... A46: 46148 | B46: 46163 | C46: TBC | D46: RoadCraft | E46: 39.99 | F46: =E46*(1-G46) -> 27.993 | G46: 0.3

Sheet Snow 2025
A1: 2025
A2: Start Date | B2: End Date | C2: Program | D2: Content Name | E2: Current SRP ($USD) | F2: Promo SRP ($USD) | G2: Discount % | H2: Release
A3: STEAM
A4: 45670 | B4: 45684 | C4: Custom promo January | D4: SnowRunner | E4: 29.99 | F4: =E4*(1-G4) -> 14.995 | G4: 0.5
A5: 45670 | B5: 45684 | C5: Custom promo January | D5: SnowRunner - 1 year anniversary | E5: 39.99 | F5: =E5*(1-G5) -> 19.995 | G5: 0.5
A6: 45670 | B6: 45684 | C6: Custom promo January | D6: SnowRunner - 2 year anniversary | E6: 64.77 | F6: =E6*(1-G6) -> 34.9758 | G6: 0.46
A7: 45670 | B7: 45684 | C7: Custom promo January | D7: SnowRunner - 3 year anniversary | E7: 84.99 | F7: =E7*(1-G7) -> 50.994 | G7: 0.4
A8: 45670 | B8: 45684 | C8: Custom promo January | D8: SnowRunner - 4 year anniversary | E8: 104.99 | F8: =E8*(1-G8) -> 75.5928 | G8: 0.28
A9: 45670 | B9: 45684 | C9: Custom promo January | D9: Snowrunner all seasons except before 12 | E9: 6.99 | F9: =E9*(1-G9) -> 4.5435 | G9: 0.35
A10: 45670 | B10: 45684 | C10: Custom promo January | D10: Season 12 | E10: 11.99 | F10: =E10*(1-G10) -> 7.7935 | G10: 0.35 | H10: Jan. 2024
A11: 45670 | B11: 45684 | C11: Custom promo January | D11: Season 13 | E11: 6.99 | F11: =E11*(1-G11) -> 4.893 | G11: 0.3 | H11: 45444
A12: 45670 | B12: 45684 | C12: Custom promo January | D12: Season 14 | E12: 6.99 | F12: =E12*(1-G12) -> 5.2425 | G12: 0.25 | H12: 45536
A13: 45670 | B13: 45684 | C13: Custom promo January | D13: Snowrunner all Vehicules | E13: 3.99 | F13: =E13*(1-G13) -> 3.192 | G13: 0.2
A14: 45670 | B14: 45684 | C14: Custom promo January | D14: SnowRunner Year 1 Pass | E14: 24.99 | F14: =E14*(1-G14) -> 17.493 | G14: 0.3
A15: 45670 | B15: 45684 | C15: Custom promo January | D15: SnowRunner Year 2 Pass | E15: 24.99 | F15: =E15*(1-G15) -> 17.493 | G15: 0.3
A16: 45670 | B16: 45684 | C16: Custom promo January | D16: SnowRunner Year 3 Pass | E16: 24.99 | F16: =E16*(1-G16) -> 18.7425 | G16: 0.25
A17: 45670 | B17: 45684 | C17: Custom promo January | D17: SnowRunner Year 4 Pass | E17: 24.99 | F17: =E17*(1-G17) -> 24.99 | G17: 0
A19: 45715 | B19: 45727 | C19: Custom promo late Feb | D19: SnowRunner | E19: 29.99 | F19: =E19*(1-G19) -> 14.995 | G19: 0.5
A20: 45715 | B20: 45727 | C20: Custom promo late Feb | D20: SnowRunner - 1 year anniversary | E20: 39.99 | F20: =E20*(1-G20) -> 19.995 | G20: 0.5
A21: 45715 | B21: 45727 | C21: Custom promo late Feb | D21: SnowRunner - 2 year anniversary | E21: 64.77 | F21: =E21*(1-G21) -> 34.9758 | G21: 0.46
A22: 45715 | B22: 45727 | C22: Custom promo late Feb | D22: SnowRunner - 3 year anniversary | E22: 84.99 | F22: =E22*(1-G22) -> 50.994 | G22: 0.4
A23: 45715 | B23: 45727 | C23: Custom promo late Feb | D23: SnowRunner - 4 year anniversary | E23: 104.99 | F23: =E23*(1-G23) -> 75.5928 | G23: 0.28
A24: 45715 | B24: 45727 | C24: Custom promo late Feb | D24: Snowrunner all seasons except before 12 | E24: 6.99 | F24: =E24*(1-G24) -> 4.5435 | G24: 0.35
A25: 45715 | B25: 45727 | C25: Custom promo late Feb | D25: Season 12 | E25: 11.99 | F25: =E25*(1-G25) -> 7.7935 | G25: 0.35 | H25: Jan. 2024
A26: 45715 | B26: 45727 | C26: Custom promo late Feb | D26: Season 13 | E26: 6.99 | F26: =E26*(1-G26) -> 4.893 | G26: 0.3 | H26: 45444
A27: 45715 | B27: 45727 | C27: Custom promo late Feb | D27: Season 14 | E27: 6.99 | F27: =E27*(1-G27) -> 5.2425 | G27: 0.25 | H27: 45536
A28: 45715 | B28: 45727 | C28: Custom promo late Feb | D28: Snowrunner all Vehicules | E28: 3.99 | F28: =E28*(1-G28) -> 3.192 | G28: 0.2
A29: 45715 | B29: 45727 | C29: Custom promo late Feb | D29: SnowRunner Year 1 Pass | E29: 24.99 | F29: =E29*(1-G29) -> 17.493 | G29: 0.3
A30: 45715 | B30: 45727 | C30: Custom promo late Feb | D30: SnowRunner Year 2 Pass | E30: 24.99 | F30: =E30*(1-G30) -> 17.493 | G30: 0.3
A31: 45715 | B31: 45727 | C31: Custom promo late Feb | D31: SnowRunner Year 3 Pass | E31: 24.99 | F31: =E31*(1-G31) -> 18.7425 | G31: 0.25
A32: 45715 | B32: 45727 | C32: Custom promo late Feb | D32: SnowRunner Year 4 Pass | E32: 24.99 | F32: =E32*(1-G32) -> 24.99 | G32: 0
A34: 45729 | B34: 45734 | C34: Spring Sales | D34: SnowRunner | E34: 29.99 | F34: =E34*(1-G34) -> 14.995 | G34: 0.5
A35: 45729 | B35: 45734 | C35: Spring Sales | D35: SnowRunner - 1 year anniversary | E35: 39.99 | F35: =E35*(1-G35) -> 19.995 | G35: 0.5
A36: 45729 | B36: 45734 | C36: Spring Sales | D36: SnowRunner - 2 year anniversary | E36: 64.77 | F36: =E36*(1-G36) -> 34.9758 | G36: 0.46
A37: 45729 | B37: 45734 | C37: Spring Sales | D37: SnowRunner - 3 year anniversary | E37: 84.99 | F37: =E37*(1-G37) -> 50.994 | G37: 0.4
A38: 45729 | B38: 45734 | C38: Spring Sales | D38: SnowRunner - 4 year anniversary | E38: 104.99 | F38: =E38*(1-G38) -> 75.5928 | G38: 0.28
A39: 45729 | B39: 45734 | C39: Spring Sales | D39: Snowrunner all seasons except before 12 | E39: 6.99 | F39: =E39*(1-G39) -> 4.5435 | G39: 0.35
A40: 45729 | B40: 45734 | C40: Spring Sales | D40: Season 12 | E40: 11.99 | F40: =E40*(1-G40) -> 7.7935 | G40: 0.35 | H40: Jan. 2024
A41: 45729 | B41: 45734 | C41: Spring Sales | D41: Season 13 | E41: 6.99 | F41: =E41*(1-G41) -> 4.893 | G41: 0.3 | H41: 45444
A42: 45729 | B42: 45734 | C42: Spring Sales | D42: Season 14 | E42: 6.99 | F42: =E42*(1-G42) -> 5.2425 | G42: 0.25 | H42: 45536
...

Sheet Expe 2025
A1: 2025
A2: Start Date | B2: End Date | C2: Program | D2: Content Name | E2: Current SRP ($USD) | F2: Promo SRP ($USD) | G2: Discount %
A3: STEAM
A4: 45715 | B4: 45729 | C4: Custom Deal January | D4: Expeditions Base Game | E4: 39.99 | F4: =E4*(1-G4) -> 23.994 | G4: 0.4
A5: 45715 | B5: 45729 | C5: Custom Deal January | D5: Expeditions Year 1 Edition | E5: 59.99 | F5: =E5*(1-G5) -> 35.994 | G5: 0.4
A6: 45715 | B6: 45729 | C6: Custom Deal January | D6: Expeditions Supreme Edition | E6: 69.99 | F6: =E6*(1-G6) -> 39.8943 | G6: 0.43
A7: 45715 | B7: 45729 | C7: Custom Deal January | D7: Expeditions Year 1 pass | E7: 29.99 | F7: =E7*(1-G7) -> 22.4925 | G7: 0.25
A8: 45715 | B8: 45729 | C8: Custom Deal January | D8: Expeditions Pioneer pack | E8: 11.99 | F8: =E8*(1-G8) -> 8.9925 | G8: 0.25
A9: 45715 | B9: 45729 | C9: Custom Deal January | D9: Expeditions the Great Don 71 | E9: 2.99 | F9: =E9*(1-G9) -> 2.392 | G9: 0.2
A10: 45715 | B10: 45729 | C10: Custom Deal January | D10: Expeditions cotto canyon | E10: 2.99 | F10: =E10*(1-G10) -> 2.392 | G10: 0.2
A11: 45715 | B11: 45729 | C11: Custom Deal January | D11: Saison 1 | E11: 6.99 | F11: =E11*(1-G11) -> 5.2425 | G11: 0.25
A14: 45729 | B14: 45734 | C14: Spring Sales | D14: Expeditions Base Game | E14: 39.99 | F14: =E14*(1-G14) -> 23.994 | G14: 0.4
A15: 45729 | B15: 45734 | C15: Spring Sales | D15: Expeditions Year 1 Edition | E15: 59.99 | F15: =E15*(1-G15) -> 35.994 | G15: 0.4
A16: 45729 | B16: 45734 | C16: Spring Sales | D16: Expeditions Supreme Edition | E16: 69.99 | F16: =E16*(1-G16) -> 39.8943 | G16: 0.43
A17: 45729 | B17: 45734 | C17: Spring Sales | D17: Expeditions Year 1 pass | E17: 29.99 | F17: =E17*(1-G17) -> 22.4925 | G17: 0.25
... A31: 45759 | B31: 45766 | C31: Custom Sales | D31: Saison 1 | E31: 6.99 | F31: =E31*(1-G31) -> 5.2425 | G31: 0.25
A32: 45759 | B32: 45766 | C32: Custom Sales | D32: Saison 2 | E32: 6.99 | F32: =E32*(1-G32) -> 6.99 | G32: 0 | H32: février
A34: 45796 | B34: 45810 | C34: Custom Sales | D34: Expeditions Base Game | E34: 39.99 | F34: =E34*(1-G34) -> 23.994 | G34: 0.4
A35: 45796 | B35: 45810 | C35: Custom Sales | D35: Expeditions Year 1 Edition | E35: 59.99 | F35: =E35*(1-G35) -> 35.994 | G35: 0.4
A36: 45796 | B36: 45810 | C36: Custom Sales | D36: Expeditions Supreme Edition | E36: 69.99 | F36: =E36*(1-G36) -> 39.8943 | G36: 0.43
A37: 45796 | B37: 45810 | C37: Custom Sales | D37: Expeditions Year 1 pass | E37: 29.99 | F37: =E37*(1-G37) -> 22.4925 | G37: 0.25
A38: 45796 | B38: 45810 | C38: Custom Sales | D38: Expeditions Pioneer pack | E38: 11.99 | F38: =E38*(1-G38) -> 8.9925 | G38: 0.25
A39: 45796 | B39: 45810 | C39: Custom Sales | D39: Expeditions the Great Don 71 | E39: 2.99 | F39: =E39*(1-G39) -> 2.392 | G39: 0.2
A40: 45796 | B40: 45810 | C40: Custom Sales | D40: Expeditions cotto canyon | E40: 2.99 | F40: =E40*(1-G40) -> 2.392 | G40: 0.2
A41: 45796 | B41: 45810 | C41: Custom Sales | D41: Saison 1 | E41: 6.99 | F41: =E41*(1-G41) -> 5.2425 | G41: 0.25
A42: 45796 | B42: 45810 | C42: Custom Sales | D42: Saison 2 | E42: 6.99 | F42: =E42*(1-G42) -> 5.592 | G42: 0.2 | H42: février
A44: 45834 | B44: 45848 | C44: Summer promo | D44: Expeditions Base Game | E44: 39.99 | F44: =E44*(1-G44) -> 19.995 | G44: 0.5
A45: 45834 | B45: 45848 | C45: Summer promo | D45: Expeditions Year 1 Edition | E45: 59.99 | F45: =E45*(1-G45) -> 29.995 | G45: 0.5
A46: 45834 | B46: 45848 | C46: Summer promo | D46: Expeditions Supreme Edition | E46: 69.99 | F46: =E46*(1-G46) -> 34.995 | G46: 0.5
A47: 45834 | B47: 45848 | C47: Summer promo | D47: Expeditions Year 1 pass | E47: 29.99 | F47: =E47*(1-G47) -> 22.4925 | G47: 0.25
A48: 45834 | B48: 45848 | C48: Summer promo | D48: Expeditions Pioneer pack | E48: 11.99 | F48: =E48*(1-G48) -> 8.9925 | G48: 0.25
A49: 45834 | B49: 45848 | C49: Summer promo | D49: Expeditions the Great Don 71 | E49: 2.99 | F49: =E49*(1-G49) -> 2.392 | G49: 0.2
A50: 45834 | B50: 45848 | C50: Summer promo | D50: Expeditions cotto canyon | E50: 2.99 | F50: =E50*(1-G50) -> 2.392 | G50: 0.2
A51: 45834 | B51: 45848 | C51: Summer promo | D51: Saison 1 | E51: 6.99 | F51: =E51*(1-G51) -> 5.2425 | G51: 0.25
A52: 45834 | B52: 45848 | C52: Summer promo | D52: Saison 2 | E52: 6.99 | F52: =E52*(1-G52) -> 5.592 | G52: 0.2 | H52: février
A54: 45848 | B54: 45862 | C54: Custom July | D54: Expeditions Base Game | E54: 39.99 | F54: =E54*(1-G54) -> 19.995 | G54: 0.5
A55: 45848 | B55: 45862 | C55: Custom July | D55: Expeditions Year 1 Edition | E55: 59.99 | F55: =E55*(1-G55) -> 29.995 | G55: 0.5
A56: 45848 | B56: 45862 | C56: Custom July | D56: Expeditions Supreme Edition | E56: 69.99 | F56: =E56*(1-G56) -> 34.995 | G56: 0.5
A57: 45848 | B57: 45862 | C57: Custom July | D57: Expeditions Year 1 pass | E57: 29.99 | F57: =E57*(1-G57) -> 22.4925 | G57: 0.25
A58: 45848 | B58: 45862 | C58: Custom July | D58: Expeditions Pioneer pack | E58: 11.99 | F58: =E58*(1-G58) -> 8.9925 | G58: 0.25
...

Sheet ISS 2025
A1: 2025
A2: Start Date | B2: End Date | C2: Program | D2: Content Name | E2: Current SRP ($USD) | F2: Promo SRP ($USD) | G2: Discount %
A3: STEAM
A4: 45698 | B4: 45712 | C4: Custom Games from Quebec | D4: Insurgency Sandstorm | E4: 29.99 | F4: =E4*(1-G4) -> 9.8967 | G4: 0.67
A5: 45698 | B5: 45712 | C5: Custom Games from Quebec | D5: Insurgency Sandstorm Deluxe Edition | E5: 39.99 | F5: =E5*(1-G5) -> 13.9965 | G5: 0.65
A6: 45698 | B6: 45712 | C6: Custom Games from Quebec | D6: Insurgency Sandstorm Gold Edition | E6: 59.99 | F6: =E6*(1-G6) -> 17.997 | G6: 0.7
A7: 45698 | B7: 45712 | C7: Custom Games from Quebec | D7: Insurgency Sandstorm Ultimate Edition | E7: 69.99 | F7: =E7*(1-G7) -> 34.995 | G7: 0.5
A8: 45698 | B8: 45712 | C8: Custom Games from Quebec | D8: Insurgency Sandstorm Year Pass 1 | E8: 24.99 | F8: =E8*(1-G8) -> 12.495 | G8: 0.5
A9: 45698 | B9: 45712 | C9: Custom Games from Quebec | D9: Insurgency Sandstorm Year Pass 2 | E9: 29.99 | F9: =E9*(1-G9) -> 14.995 | G9: 0.5
A10: 45698 | B10: 45712 | C10: Custom Games from Quebec | D10: Insurgency Sandstorm Year Pass 3 | E10: 34.99 | F10: =E10*(1-G10) -> 24.493 | G10: 0.3
A11: 45698 | B11: 45712 | C11: Custom Games from Quebec | D11: Insurgency Sandstorm Year Pass 1 + 2 | E11: 44.99 | F11: =E11*(1-G11) -> 22.495 | G11: 0.5
A12: 45698 | B12: 45712 | C12: Custom Games from Quebec | D12: Insurgency Sandstorm Year Pass 1 + 2+3 | E12: 59.99 | F12: =E12*(1-G12) -> 41.993 | G12: 0.3
A14: 45729 | B14: 45734 | C14: Spring Sales | D14: Insurgency Sandstorm | E14: 29.99 | F14: =E14*(1-G14) -> 9.8967 | G14: 0.67
A15: 45729 | B15: 45734 | C15: Spring Sales | D15: Insurgency Sandstorm Deluxe Edition | E15: 39.99 | F15: =E15*(1-G15) -> 13.9965 | G15: 0.65
A16: 45729 | B16: 45734 | C16: Spring Sales | D16: Insurgency Sandstorm Gold Edition | E16: 59.99 | F16: =E16*(1-G16) -> 17.997 | G16: 0.7
... A22: 45729 | B22: 45734 | C22: Spring Sales | D22: Insurgency Sandstorm Year Pass 1 + 2+3 | E22: 59.99 | F22: =E22*(1-G22) -> 41.993 | G22: 0.3
A24: 12 /04 | B24: 45773 | C24: Custom Deal | D24: Insurgency Sandstorm | E24: 29.99 | F24: =E24*(1-G24) -> 9.8967 | G24: 0.67
A25: 12 /04 | B25: 45773 | C25: Custom Deal | D25: Insurgency Sandstorm Deluxe Edition | E25: 39.99 | F25: =E25*(1-G25) -> 13.9965 | G25: 0.65
A26: 12 /04 | B26: 45773 | C26: Custom Deal | D26: Insurgency Sandstorm Gold Edition | E26: 59.99 | F26: =E26*(1-G26) -> 17.997 | G26: 0.7
A27: 12 /04 | B27: 45773 | C27: Custom Deal | D27: Insurgency Sandstorm Ultimate Edition | E27: 69.99 | F27: =E27*(1-G27) -> 34.995 | G27: 0.5
A28: 12 /04 | B28: 45773 | C28: Custom Deal | D28: Insurgency Sandstorm Year Pass 1 | E28: 24.99 | F28: =E28*(1-G28) -> 12.495 | G28: 0.5
A29: 12 /04 | B29: 45773 | C29: Custom Deal | D29: Insurgency Sandstorm Year Pass 2 | E29: 29.99 | F29: =E29*(1-G29) -> 14.995 | G29: 0.5
A30: 12 /04 | B30: 45773 | C30: Custom Deal | D30: Insurgency Sandstorm Year Pass 3 | E30: 34.99 | F30: =E30*(1-G30) -> 24.493 | G30: 0.3
A31: 12 /04 | B31: 45773 | C31: Custom Deal | D31: Insurgency Sandstorm Year Pass 1 + 2 | E31: 44.99 | F31: =E31*(1-G31) -> 22.495 | G31: 0.5
A32: 12 /04 | B32: 45773 | C32: Custom Deal | D32: Insurgency Sandstorm Year Pass 1 + 2+3 | E32: 59.99 | F32: =E32*(1-G32) -> 41.993 | G32: 0.3
A34: 45803 | B34: 45817 | C34: Midweek madness extended | D34: Insurgency Sandstorm | E34: 29.99 | F34: =E34*(1-G34) -> 9.8967 | G34: 0.67
A35: 45803 | B35: 45817 | C35: Midweek madness extended | D35: Insurgency Sandstorm Deluxe Edition | E35: 39.99 | F35: =E35*(1-G35) -> 13.9965 | G35: 0.65
A36: 45803 | B36: 45817 | C36: Midweek madness extended | D36: Insurgency Sandstorm Gold Edition | E36: 59.99 | F36: =E36*(1-G36) -> 17.997 | G36: 0.7
A37: 45803 | B37: 45817 | C37: Midweek madness extended | D37: Insurgency Sandstorm Ultimate Edition | E37: 69.99 | F37: =E37*(1-G37) -> 34.995 | G37: 0.5
A38: 45803 | B38: 45817 | C38: Midweek madness extended | D38: Insurgency Sandstorm Year Pass 1 | E38: 24.99 | F38: =E38*(1-G38) -> 12.495 | G38: 0.5
A39: 45803 | B39: 45817 | C39: Midweek madness extended | D39: Insurgency Sandstorm Year Pass 2 | E39: 29.99 | F39: =E39*(1-G39) -> 14.995 | G39: 0.5
A40: 45803 | B40: 45817 | C40: Midweek madness extended | D40: Insurgency Sandstorm Year Pass 3 | E40: 34.99 | F40: =E40*(1-G40) -> 24.493 | G40: 0.3
A41: 45803 | B41: 45817 | C41: Midweek madness extended | D41: Insurgency Sandstorm Year Pass 1 + 2 | E41: 44.99 | F41: =E41*(1-G41) -> 22.495 | G41: 0.5
A42: 45803 | B42: 45817 | C42: Midweek madness extended | D42: Insurgency Sandstorm Year Pass 1 + 2+3 | E42: 59.99 | F42: =E42*(1-G42) -> 41.993 | G42: 0.3
A44: 45834 | B44: 45848 | C44: Summer promo | D44: Insurgency Sandstorm | E44: 29.99 | F44: =E44*(1-G44) -> 9.8967 | G44: 0.67
A45: 45834 | B45: 45848 | C45: Summer promo | D45: Insurgency Sandstorm Deluxe Edition | E45: 39.99 | F45: =E45*(1-G45) -> 13.9965 | G45: 0.65 | H45: =F45-F44 -> 4.0998
A46: 45834 | B46: 45848 | C46: Summer promo | D46: Insurgency Sandstorm Gold Edition | E46: 59.99 | F46: =E46*(1-G46) -> 17.997 | G46: 0.7
A47: 45834 | B47: 45848 | C47: Summer promo | D47: Insurgency Sandstorm Ultimate Edition | E47: 69.99 | F47: =E47*(1-G47) -> 34.995 | G47: 0.5
A48: 45834 | B48: 45848 | C48: Summer promo | D48: Insurgency Sandstorm Year Pass 1 | E48: 24.99 | F48: =E48*(1-G48) -> 12.495 | G48: 0.5
A49: 45834 | B49: 45848 | C49: Summer promo | D49: Insurgency Sandstorm Year Pass 2 | E49: 29.99 | F49: =E49*(1-G49) -> 14.995 | G49: 0.5
...

Sheet ISS 2024
A1: 2024
A2: Partner | B2: Start Date | C2: End Date | D2: Program | E2: Content Name | F2: Current SRP ($USD) | G2: Promo SRP ($USD) | H2: Discount %
A3: STEAM
A4: Steam | B4: 45313 | C4: 45327 | D4: Custom deal + Games from Quebec | E4: Insurgency Sandstorm | F4: $29,99 | G4: $9,99 | H4: 0.67
A5: Steam | B5: 45313 | C5: 45327 | D5: Custom deal + Games from Quebec | E5: Insurgency Sandstorm Deluxe Edition | F5: $39,99 | G5: $16,00 | H5: 0.6
A6: Steam | B6: 45313 | C6: 45327 | D6: Custom deal + Games from Quebec | E6: Insurgency Sandstorm Gold Edition | F6: $59,99 | G6: $27,00 | H6: 0.55
A7: Steam | B7: 45313 | C7: 45327 | D7: Custom deal + Games from Quebec | E7: Insurgency Sandstorm Ultimate Edition | F7: $69,99 | G7: $55,95 | H7: 0.2
A8: Steam | B8: 45313 | C8: 45327 | D8: Custom deal + Games from Quebec | E8: Insurgency Sandstorm Year Pass 1 | F8: $24,99 | G8: $14,99 | H8: 0.4
A9: Steam | B9: 45313 | C9: 45327 | D9: Custom deal + Games from Quebec | E9: Insurgency Sandstorm Year Pass 2 | F9: $29,99 | G9: $17,99 | H9: 0.4
A10: Steam | B10: 45313 | C10: 45327 | D10: Custom deal + Games from Quebec | E10: Insurgency Sandstorm Year Pass 3 | F10: $34,99 | G10: $34,99 | H10: 0
